Workbook

Sheet Resumen
B2: Resumen ejecutivo de costos
B3: Los KPI se calculan desde Detalle_facturado, agrupando por la columna Rubro.
B5: Costo Procesamiento | E5: Costo Plataforma | H5: Costo Licenciamiento | K5: Costo Total Global
B6: =SUMIF(Detalle_facturado!$Q$2:$Q$60305,"Procesamiento",Detalle_facturado!$T$2:$T$60305) -> 65254104 | E6: =SUMIF(Detalle_facturado!$Q$2:$Q$60305,"Plataforma*",Detalle_facturado!$T$2:$T$60305) -> 63110772 | H6: =SUM(Detalle_facturado!$V$2:$V$60305) -> 49593119 | K6: =SUM(Detalle_facturado!$W$2:$W$60305) -> 1.77958e+08
B9: Costo Plataforma - Ambiente de Pruebas | H9: Costo Plataforma - Producción y Soporte
B10: =SUMIF(Detalle_facturado!$Q$2:$Q$60305,"Plataforma - Ambiente de Pruebas",Detalle_facturado!$T$2:$T$60305) -> 30281693 | H10: =SUMIF(Detalle_facturado!$Q$2:$Q$60305,"Plataforma - Producción y Soporte",Detalle_facturado!$T$2:$T$60305) -> 32829079
B13: Cómo leer Rubro
B14: Rubro clasifica cada costo como Procesamiento o Plataforma. Cada fila contiene un único importe base, Costo AWS (USD), y su conversión Costo AWS (COP), calculada con la tasa visible abajo. Cuando el rubro es Procesamiento se aplica adicionalmente la tarifa de licenciamiento; para los rubros de Plataforma el licenciamiento es cero.
B20: Trazabilidad
B21: Por_cuenta, Por_servicio y Cuenta_servicio_uso también están desagregadas por Rubro. Los KPI superiores usan SUMIF sobre Rubro en Detalle_facturado, y los controles inferiores prueban que todas las hojas suman el mismo total.
B25: Parámetros y base monetaria
B27: Tasa de cambio | C27: 3655.16 | E27: Costo AWS total | F27: =SUM(Detalle_facturado!$R$2:$R$60305) -> 35118.812 | G27: USD
B28: Tarifa de licenciamiento | C28: 0.76 | E28: Costo AWS convertido | F28: =F27*$C$27 -> 1.2836488e+08 | G28: COP

Sheet Analisis de Costos
A1: ANALISIS EJECUTIVO DE COSTOS
A2: ="Periodo: "&TEXT(MIN(Detalle_facturado!A2:A100000),"DD/MM/YYYY")&" al "&TEXT(MAX(Detalle_facturado!A2:A100000),"DD/MM/YYYY")&" | Fuente: Detalle_facturado | Actualizacion automatica al recalcular" -> Periodo: 25/07/2026 al 27/08/2026 | Fuente: Detalle_facturado | Actualizacion automatica al recalcular | N2: DATO | O2: Valor inicial | P2: Enterprise support | Q2: Ambientes de prueba | R2: Ambos | S2: AMBOS + TRM | T2: Ambos Houndoc | U2: MAP | V2: Entreprise support a Bussines suuport | W2: TRM | X2: Ambientes prueba
A3: TOTAL FACTURABLE | D3: COSTO AWS | G3: LICENCIAMIENTO | J3: % LICENCIAMIENTO | N3: CANTIDAD DE AUDITORIAS | O3: 3241 | P3: 3241 | Q3: 3241 | R3: 3241 | S3: 3241 | T3: 3241 | U3: 3241 | V3: 3241 | W3: 3241 | X3: 3241 | AK3: Componente | AL3: COP
A4: =SUM(Detalle_facturado!W2:W100000) -> 1.77958e+08 | D4: =SUM(Detalle_facturado!T2:T100000) -> 1.2836488e+08 | G4: =SUM(Detalle_facturado!V2:V100000) -> 49593119 | J4: =IFERROR(G4/A4,0) -> 0.27867879 | N4: Valor promedio auditoria | O4: =+A4/O3 -> 54908.36 | P4: =+P5/P3 -> 51976.24 | Q4: =+Q5/Q3 -> 45565.042 | R4: =+R5/R3 -> 39700.803 | S4: =+S5/S3 -> 37474.082 | T4: =+T5/T3 -> 34259.025 | U4: =+U5/U3 -> 36341.464 | V4: =+V5/V3 -> 33409.344 | W4: =+W5/W3 -> 31535.496 | X4: =+X5/X3 -> 30294.905 | AK4: Procesamiento AWS | AL4: =SUMIF(Detalle_facturado!Q2:Q100000,"Procesamiento",Detalle_facturado!T2:T100000) -> 65254104
N5: VALOR TOTAL | O5: =+A4 -> 1.77958e+08 | P5: =+O5-P6 -> 1.68455e+08 | Q5: =+O5-Q6 -> 1.476763e+08 | R5: =+P5-R6 -> 1.286703e+08 | S5: =+R5/O8*3450 -> 1.214535e+08 | T5: =+S5-T6 -> 1.110335e+08 | U5: =+O5-U6 -> 1.1778268e+08 | V5: =+$O$5-V6 -> 1.0827968e+08 | W5: =+V5/O8*3450 -> 1.0220654e+08 | X5: =+$O$5-X6 -> 98185787 | AK5: Plataforma prod. y soporte | AL5: =SUMIF(Detalle_facturado!Q2:Q100000,"Plataforma - Producción y Soporte",Detalle_facturado!T2:T100000) -> 32829079
N6: Despuento acumulado | P6: =2600*O8 -> 9503000 | Q6: =+G8 -> 30281693 | R6: =+Q6+P6 -> 39784693 | T6: 10420000 | U6: =+U8/6 -> 60175310 | V6: =+U6+P6 -> 69678310 | X6: =+V6+Q6/3 -> 79772208 | AK6: Plataforma pruebas | AL6: =SUMIF(Detalle_facturado!Q2:Q100000,"Plataforma - Ambiente de Pruebas",Detalle_facturado!T2:T100000) -> 30281693
A7: PROCESAMIENTO AWS | D7: PLATAFORMA PROD. Y SOPORTE | G7: PLATAFORMA AMBIENTE DE PRUEBAS | J7: % GENAI | O7: TRM | AK7: Licenciamiento | AL7: =SUM(Detalle_facturado!V2:V100000) -> 49593119
A8: =SUMIF(Detalle_facturado!Q2:Q100000,"Procesamiento",Detalle_facturado!T2:T100000) -> 65254104 | D8: =SUMIF(Detalle_facturado!Q2:Q100000,"Plataforma - Producción y Soporte",Detalle_facturado!T2:T100000) -> 32829079 | G8: =SUMIF(Detalle_facturado!Q2:Q100000,"Plataforma - Ambiente de Pruebas",Detalle_facturado!T2:T100000) -> 30281693 | J8: =IFERROR(SUMIF(Detalle_facturado!AB2:AB100000,"GenAI",Detalle_facturado!W2:W100000)/A4,0) -> 0.70056542 | O8: 3655 | U8: 361051863
T10: RADICACION | U10: Mayo | V10: Junio | W10: Julio
A11: COMPORTAMIENTO Y COMPOSICION | T11: PROCESAMIENTO | U11: Julio | V11: Aug | W11: Sep | X11: oct | Y11: Nov | Z11: Dec | AA11: Jan | AB11: Feb | AC11: Mar | AD11: Apr | AE11: May | AF11: Jun
U12: 3241 | V12: 5250 | W12: =+V12 -> 5250 | X12: =+W12 -> 5250 | Y12: =+X12 -> 5250 | Z12: =+Y12 -> 5250 | AA12: =+Z12 -> 5250 | AB12: =+AA12 -> 5250 | AC12: =+AB12 -> 5250 | AD12: =+AC12 -> 5250 | ... AF12: =+AE12 -> 5250 | AK12: Servicio | AL12: Total facturable COP | AM12: Ranking | AO12: Categoria | AP12: Total facturable COP | AQ12: Ranking | AS12: Cuenta | AT12: Total facturable COP | AV12: Ambiente | AW12: Total facturable COP | AY12: Fecha | AZ12: Total facturable COP | BA12: Costo AWS COP | BC12: Modelo | BD12: Costo AWS COP | BE12: Licenciamiento COP | BF12: Servicio exacto | BH12: Categoria | BI12: Costo AWS COP | BJ12: Licenciamiento COP | BL12: Cuenta | BM12: Procesamiento facturable | BN12: Plataforma prod. y soporte | BO12: Plataforma pruebas | BQ12: Fecha | BR12: Procesamiento AWS | BS12: Plataforma prod. y soporte | BT12: Plataforma pruebas
U13: =+U12*4.5 -> 14584.5 | V13: =+V12*4.5 -> 23625 | W13: =+W12*4.5 -> 23625 | X13: =+X12*4.5 -> 23625 | Y13: =+Y12*4.5 -> 23625 | Z13: =+Z12*4.5 -> 23625 | AA13: =+AA12*4.5 -> 23625 | AB13: =+AB12*4.5 -> 23625 | ... AF13: =+AF12*4.5 -> 23625 | AK13: Claude Opus 4.6 (Amazon Bedrock Edition) | AL13: =SUMIF(Detalle_facturado!F2:F100000,AK13,Detalle_facturado!W2:W100000) -> 1.2091155e+08 | AM13: =RANK(AL13,$AL$13:$AL$76,0)+COUNTIF($AL$13:AL13,AL13)-1 -> 1 | AO13: GenAI | AP13: =SUMIF(Detalle_facturado!AB2:AB100000,AO13,Detalle_facturado!W2:W100000) -> 1.2467122e+08 | AQ13: =RANK(AP13,$AP$13:$AP$34,0)+COUNTIF($AP$13:AP13,AP13)-1 -> 1 | AS13: ADRES - PROD - Medical Audit | AT13: =SUMIF(Detalle_facturado!D2:D100000,AS13,Detalle_facturado!W2:W100000) -> 1.2261071e+08 | AV13: Prod | AW13: =SUMIF(Detalle_facturado!E2:E100000,AV13,Detalle_facturado!W2:W100000) -> 1.4557607e+08 | AY13: =INT(MIN(Detalle_facturado!A2:A100000)) -> 46228 | AZ13: =IF(ISNA(AY13),NA(),SUMIFS(Detalle_facturado!W2:W100000,Detalle_facturado!A2:A100000,">="&AY13,Detalle_facturado!A2:A100000,"<"&AY13+1)) -> 2081954.5 | BA13: =IF(ISNA(AY13),NA(),SUMIFS(Detalle_facturado!T2:T100000,Detalle_facturado!A2:A100000,">="&AY13,Detalle_facturado!A2:A100000,"<"&AY13+1)) -> 2081919.2 | BC13: Claude Opus 4.6 | BD13: =SUMIF(Detalle_facturado!F2:F100000,BF13,Detalle_facturado!T2:T100000) -> 72900872 | BE13: =SUMIF(Detalle_facturado!F2:F100000,BF13,Detalle_facturado!V2:V100000) -> 48010675 | BF13: Claude Opus 4.6 (Amazon Bedrock Edition) | BH13: =AO81 -> GenAI | BI13: =SUMIF(Detalle_facturado!AB2:AB100000,BH13,Detalle_facturado!T2:T100000) -> 75192344 | BJ13: =SUMIF(Detalle_facturado!AB2:AB100000,BH13,Detalle_facturado!V2:V100000) -> 49478873 | BL13: =AS13 -> ADRES - PROD - Medical Audit | BM13: =IF(SUMIFS(Detalle_facturado!W2:W100000,Detalle_facturado!D2:D100000,BL13,Detalle_facturado!Q2:Q100000,"Procesamiento")=0,NA(),SUMIFS(Detalle_facturado!W2:W100000,Detalle_facturado!D2:D100000,BL13,Detalle_facturado!Q2:Q100000,"Procesamiento")) -> 1.1484722e+08 | BN13: =IF(SUMIFS(Detalle_facturado!W2:W100000,Detalle_facturado!D2:D100000,BL13,Detalle_facturado!Q2:Q100000,"Plataforma - Producción y Soporte")=0,NA(),SUMIFS(Detalle_facturado!W2:W100000,Detalle_facturado!D2:D100000,BL13,Detalle_facturado!Q2:Q100000,"Plataforma - Producción y Soporte")) -> 7763482.2 | BO13: =IF(SUMIFS(Detalle_facturado!W2:W100000,Detalle_facturado!D2:D100000,BL13,Detalle_facturado!Q2:Q100000,"Plataforma - Ambiente de Pruebas")=0,NA(),SUMIFS(Detalle_facturado!W2:W100000,Detalle_facturado!D2:D100000,BL13,Detalle_facturado!Q2:Q100000,"Plataforma - Ambiente de Pruebas")) -> #N/A | BQ13: =AY13 -> 46228 | BR13: =SUMIFS(Detalle_facturado!T2:T100000,Detalle_facturado!A2:A100000,">="&BQ13,Detalle_facturado!A2:A100000,"<"&BQ13+1,Detalle_facturado!Q2:Q100000,"Procesamiento") -> 46.517039 | BS13: =SUMIFS(Detalle_facturado!T2:T100000,Detalle_facturado!A2:A100000,">="&BQ13,Detalle_facturado!A2:A100000,"<"&BQ13+1,Detalle_facturado!Q2:Q100000,"Plataforma - Producción y Soporte") -> 270280.26 | BT13: =SUMIFS(Detalle_facturado!T2:T100000,Detalle_facturado!A2:A100000,">="&BQ13,Detalle_facturado!A2:A100000,"<"&BQ13+1,Detalle_facturado!Q2:Q100000,"Plataforma - Ambiente de Pruebas") -> 1811592.4
U14: =+U13*3650 -> 53233425 | V14: =+V13*3650 -> 86231250 | W14: =+W13*3650 -> 86231250 | X14: =+X13*3650 -> 86231250 | Y14: =+Y13*3650 -> 86231250 | Z14: =+Z13*3650 -> 86231250 | AA14: =+AA13*3650 -> 86231250 | AB14: =+AB13*3650 -> 86231250 | ... AF14: =+AF13*3650 -> 86231250 | AK14: Claude Haiku 4.5 (Amazon Bedrock Edition) | AL14: =SUMIF(Detalle_facturado!F2:F100000,AK14,Detalle_facturado!W2:W100000) -> 1818206.6 | AM14: =RANK(AL14,$AL$13:$AL$76,0)+COUNTIF($AL$13:AL14,AL14)-1 -> 8 | AO14: Computo | AP14: =SUMIF(Detalle_facturado!AB2:AB100000,AO14,Detalle_facturado!W2:W100000) -> 0 | AQ14: =RANK(AP14,$AP$13:$AP$34,0)+COUNTIF($AP$13:AP14,AP14)-1 -> 22 | AS14: ADRES - TEST - Medical Audit | AT14: =SUMIF(Detalle_facturado!D2:D100000,AS14,Detalle_facturado!W2:W100000) -> 30281693 | AV14: Test | AW14: =SUMIF(Detalle_facturado!E2:E100000,AV14,Detalle_facturado!W2:W100000) -> 32381923 | AY14: =IF(AY13<INT(MAX(Detalle_facturado!A2:A100000)),AY13+1,NA()) -> 46229 | AZ14: =IF(ISNA(AY14),NA(),SUMIFS(Detalle_facturado!W2:W100000,Detalle_facturado!A2:A100000,">="&AY14,Detalle_facturado!A2:A100000,"<"&AY14+1)) -> 1335192.5 | BA14: =IF(ISNA(AY14),NA(),SUMIFS(Detalle_facturado!T2:T100000,Detalle_facturado!A2:A100000,">="&AY14,Detalle_facturado!A2:A100000,"<"&AY14+1)) -> 1335155.3 | BC14: Claude Haiku 4.5 | BD14: =SUMIF(Detalle_facturado!F2:F100000,BF14,Detalle_facturado!T2:T100000) -> 1072780.7 | BE14: =SUMIF(Detalle_facturado!F2:F100000,BF14,Detalle_facturado!V2:V100000) -> 745425.87 | BF14: Claude Haiku 4.5 (Amazon Bedrock Edition) | BH14: =AO82 -> Soporte AWS | BI14: =SUMIF(Detalle_facturado!AB2:AB100000,BH14,Detalle_facturado!T2:T100000) -> 20895270 | BJ14: =SUMIF(Detalle_facturado!AB2:AB100000,BH14,Detalle_facturado!V2:V100000) -> 0 | BL14: =AS14 -> ADRES - TEST - Medical Audit | BM14: =IF(SUMIFS(Detalle_facturado!W2:W100000,Detalle_facturado!D2:D100000,BL14,Detalle_facturado!Q2:Q100000,"Procesamiento")=0,NA(),SUMIFS(Detalle_facturado!W2:W100000,Detalle_facturado!D2:D100000,BL14,Detalle_facturado!Q2:Q100000,"Procesamiento")) -> #N/A | BN14: =IF(SUMIFS(Detalle_facturado!W2:W100000,Detalle_facturado!D2:D100000,BL14,Detalle_facturado!Q2:Q100000,"Plataforma - Producción y Soporte")=0,NA(),SUMIFS(Detalle_facturado!W2:W100000,Detalle_facturado!D2:D100000,BL14,Detalle_facturado!Q2:Q100000,"Plataforma - Producción y Soporte")) -> #N/A | BO14: =IF(SUMIFS(Detalle_facturado!W2:W100000,Detalle_facturado!D2:D100000,BL14,Detalle_facturado!Q2:Q100000,"Plataforma - Ambiente de Pruebas")=0,NA(),SUMIFS(Detalle_facturado!W2:W100000,Detalle_facturado!D2:D100000,BL14,Detalle_facturado!Q2:Q100000,"Plataforma - Ambiente de Pruebas")) -> 30281693 | BQ14: =AY14 -> 46229 | BR14: =SUMIFS(Detalle_facturado!T2:T100000,Detalle_facturado!A2:A100000,">="&BQ14,Detalle_facturado!A2:A100000,"<"&BQ14+1,Detalle_facturado!Q2:Q100000,"Procesamiento") -> 48.890304 | BS14: =SUMIFS(Detalle_facturado!T2:T100000,Detalle_facturado!A2:A100000,">="&BQ14,Detalle_facturado!A2:A100000,"<"&BQ14+1,Detalle_facturado!Q2:Q100000,"Plataforma - Producción y Soporte") -> 274887.81 | BT14: =SUMIFS(Detalle_facturado!T2:T100000,Detalle_facturado!A2:A100000,">="&BQ14,Detalle_facturado!A2:A100000,"<"&BQ14+1,Detalle_facturado!Q2:Q100000,"Plataforma - Ambiente de Pruebas") -> 1060218.6
AK15: Claude Sonnet 4.6 (Amazon Bedrock Edition) | AL15: =SUMIF(Detalle_facturado!F2:F100000,AK15,Detalle_facturado!W2:W100000) -> 1413954.1 | AM15: =RANK(AL15,$AL$13:$AL$76,0)+COUNTIF($AL$13:AL15,AL15)-1 -> 11 | AO15: ML | AP15: =SUMIF(Detalle_facturado!AB2:AB100000,AO15,Detalle_facturado!W2:W100000) -> 7183.9221 | AQ15: =RANK(AP15,$AP$13:$AP$34,0)+COUNTIF($AP$13:AP15,AP15)-1 -> 18 | AS15: ADRES - PROD - Master | AT15: =SUMIF(Detalle_facturado!D2:D100000,AS15,Detalle_facturado!W2:W100000) -> 21161409 | AY15: =IF(AY14<INT(MAX(Detalle_facturado!A2:A100000)),AY14+1,NA()) -> 46230 | AZ15: =IF(ISNA(AY15),NA(),SUMIFS(Detalle_facturado!W2:W100000,Detalle_facturado!A2:A100000,">="&AY15,Detalle_facturado!A2:A100000,"<"&AY15+1)) -> 2150998.9 | BA15: =IF(ISNA(AY15),NA(),SUMIFS(Detalle_facturado!T2:T100000,Detalle_facturado!A2:A100000,">="&AY15,Detalle_facturado!A2:A100000,"<"&AY15+1)) -> 1756066.6 | BC15: Claude Sonnet 4.6 | BD15: =SUMIF(Detalle_facturado!F2:F100000,BF15,Detalle_facturado!T2:T100000) -> 879350.14 | BE15: =SUMIF(Detalle_facturado!F2:F100000,BF15,Detalle_facturado!V2:V100000) -> 534603.94 | BF15: Claude Sonnet 4.6 (Amazon Bedrock Edition) | BH15: =AO83 -> Analitica y BI | BI15: =SUMIF(Detalle_facturado!AB2:AB100000,BH15,Detalle_facturado!T2:T100000) -> 8397938.4 | BJ15: =SUMIF(Detalle_facturado!AB2:AB100000,BH15,Detalle_facturado!V2:V100000) -> 0 | BL15: =AS15 -> ADRES - PROD - Master | BM15: =IF(SUMIFS(Detalle_facturado!W2:W100000,Detalle_facturado!D2:D100000,BL15,Detalle_facturado!Q2:Q100000,"Procesamiento")=0,NA(),SUMIFS(Detalle_facturado!W2:W100000,Detalle_facturado!D2:D100000,BL15,Detalle_facturado!Q2:Q100000,"Procesamiento")) -> #N/A | BN15: =IF(SUMIFS(Detalle_facturado!W2:W100000,Detalle_facturado!D2:D100000,BL15,Detalle_facturado!Q2:Q100000,"Plataforma - Producción y Soporte")=0,NA(),SUMIFS(Detalle_facturado!W2:W100000,Detalle_facturado!D2:D100000,BL15,Detalle_facturado!Q2:Q100000,"Plataforma - Producción y Soporte")) -> 21161409 | BO15: =IF(SUMIFS(Detalle_facturado!W2:W100000,Detalle_facturado!D2:D100000,BL15,Detalle_facturado!Q2:Q100000,"Plataforma - Ambiente de Pruebas")=0,NA(),SUMIFS(Detalle_facturado!W2:W100000,Detalle_facturado!D2:D100000,BL15,Detalle_facturado!Q2:Q100000,"Plataforma - Ambiente de Pruebas")) -> #N/A | BQ15: =AY15 -> 46230 | BR15: =SUMIFS(Detalle_facturado!T2:T100000,Detalle_facturado!A2:A100000,">="&BQ15,Detalle_facturado!A2:A100000,"<"&BQ15+1,Detalle_facturado!Q2:Q100000,"Procesamiento") -> 519647.79 | BS15: =SUMIFS(Detalle_facturado!T2:T100000,Detalle_facturado!A2:A100000,">="&BQ15,Detalle_facturado!A2:A100000,"<"&BQ15+1,Detalle_facturado!Q2:Q100000,"Plataforma - Producción y Soporte") -> 290352.48 | BT15: =SUMIFS(Detalle_facturado!T2:T100000,Detalle_facturado!A2:A100000,">="&BQ15,Detalle_facturado!A2:A100000,"<"&BQ15+1,Detalle_facturado!Q2:Q100000,"Plataforma - Ambiente de Pruebas") -> 946066.32
U16: =+SUM(U14:W14) -> 225695925 | X16: =+SUM(X14:Z14) -> 258693750 | AA16: =+SUM(AA14:AC14) -> 258693750 | AD16: =+SUM(AD14:AF14) -> 258693750 | AK16: Claude Sonnet 4.5 (Amazon Bedrock Edition) | AL16: =SUMIF(Detalle_facturado!F2:F100000,AK16,Detalle_facturado!W2:W100000) -> 73443.757 | AM16: =RANK(AL16,$AL$13:$AL$76,0)+COUNTIF($AL$13:AL16,AL16)-1 -> 28 | AO16: Base de datos | AP16: =SUMIF(Detalle_facturado!AB2:AB100000,AO16,Detalle_facturado!W2:W100000) -> 2873413.7 | AQ16: =RANK(AP16,$AP$13:$AP$34,0)+COUNTIF($AP$13:AP16,AP16)-1 -> 5 | AS16: ADRES - TEST - Shared Resources | AT16: =SUMIF(Detalle_facturado!D2:D100000,AS16,Detalle_facturado!W2:W100000) -> 2100229.8 | AY16: =IF(AY15<INT(MAX(Detalle_facturado!A2:A100000)),AY15+1,NA()) -> 46231 | AZ16: =IF(ISNA(AY16),NA(),SUMIFS(Detalle_facturado!W2:W100000,Detalle_facturado!A2:A100000,">="&AY16,Detalle_facturado!A2:A100000,"<"&AY16+1)) -> 8884560 | BA16: =IF(ISNA(AY16),NA(),SUMIFS(Detalle_facturado!T2:T100000,Detalle_facturado!A2:A100000,">="&AY16,Detalle_facturado!A2:A100000,"<"&AY16+1)) -> 5813960.9 | BC16: Claude Sonnet 4.5 | BD16: =SUMIF(Detalle_facturado!F2:F100000,BF16,Detalle_facturado!T2:T100000) -> 73443.757 | BE16: =SUMIF(Detalle_facturado!F2:F100000,BF16,Detalle_facturado!V2:V100000) -> 0 | BF16: Claude Sonnet 4.5 (Amazon Bedrock Edition) | BH16: =AO84 -> Busqueda y analitica | BI16: =SUMIF(Detalle_facturado!AB2:AB100000,BH16,Detalle_facturado!T2:T100000) -> 3371362.2 | BJ16: =SUMIF(Detalle_facturado!AB2:AB100000,BH16,Detalle_facturado!V2:V100000) -> 0 | BL16: =AS16 -> ADRES - TEST - Shared Resources | BM16: =IF(SUMIFS(Detalle_facturado!W2:W100000,Detalle_facturado!D2:D100000,BL16,Detalle_facturado!Q2:Q100000,"Procesamiento")=0,NA(),SUMIFS(Detalle_facturado!W2:W100000,Detalle_facturado!D2:D100000,BL16,Detalle_facturado!Q2:Q100000,"Procesamiento")) -> #N/A | BN16: =IF(SUMIFS(Detalle_facturado!W2:W100000,Detalle_facturado!D2:D100000,BL16,Detalle_facturado!Q2:Q100000,"Plataforma - Producción y Soporte")=0,NA(),SUMIFS(Detalle_facturado!W2:W100000,Detalle_facturado!D2:D100000,BL16,Detalle_facturado!Q2:Q100000,"Plataforma - Producción y Soporte")) -> 2100229.8 | BO16: =IF(SUMIFS(Detalle_facturado!W2:W100000,Detalle_facturado!D2:D100000,BL16,Detalle_facturado!Q2:Q100000,"Plataforma - Ambiente de Pruebas")=0,NA(),SUMIFS(Detalle_facturado!W2:W100000,Detalle_facturado!D2:D100000,BL16,Detalle_facturado!Q2:Q100000,"Plataforma - Ambiente de Pruebas")) -> #N/A | BQ16: =AY16 -> 46231 | BR16: =SUMIFS(Detalle_facturado!T2:T100000,Detalle_facturado!A2:A100000,">="&BQ16,Detalle_facturado!A2:A100000,"<"&BQ16+1,Detalle_facturado!Q2:Q100000,"Procesamiento") -> 4040261.9 | BS16: =SUMIFS(Detalle_facturado!T2:T100000,Detalle_facturado!A2:A100000,">="&BQ16,Detalle_facturado!A2:A100000,"<"&BQ16+1,Detalle_facturado!Q2:Q100000,"Plataforma - Producción y Soporte") -> 363552.55 | BT16: =SUMIFS(Detalle_facturado!T2:T100000,Detalle_facturado!A2:A100000,">="&BQ16,Detalle_facturado!A2:A100000,"<"&BQ16+1,Detalle_facturado!Q2:Q100000,"Plataforma - Ambiente de Pruebas") -> 1410146.4
U17: =173035*3200 -> 553712000 | X17: =9000*3650 -> 32850000 | AA17: =94159*3650 -> 343680350 | AD17: =230282*3650 -> 840529300 | AK17: Claude Opus 4.7 (Amazon Bedrock Edition) | AL17: =SUMIF(Detalle_facturado!F2:F100000,AK17,Detalle_facturado!W2:W100000) -> 436.48961 | AM17: =RANK(AL17,$AL$13:$AL$76,0)+COUNTIF($AL$13:AL17,AL17)-1 -> 45 | AO17: Busqueda y analitica | AP17: =SUMIF(Detalle_facturado!AB2:AB100000,AO17,Detalle_facturado!W2:W100000) -> 3371362.2 | AQ17: =RANK(AP17,$AP$13:$AP$34,0)+COUNTIF($AP$13:AP17,AP17)-1 -> 4 | AS17: ADRES - PROD - Shared Resources | AT17: =SUMIF(Detalle_facturado!D2:D100000,AS17,Detalle_facturado!W2:W100000) -> 941534.9 | AY17: =IF(AY16<INT(MAX(Detalle_facturado!A2:A100000)),AY16+1,NA()) -> 46232 | AZ17: =IF(ISNA(AY17),NA(),SUMIFS(Detalle_facturado!W2:W100000,Detalle_facturado!A2:A100000,">="&AY17,Detalle_facturado!A2:A100000,"<"&AY17+1)) -> 2586464.8 | BA17: =IF(ISNA(AY17),NA(),SUMIFS(Detalle_facturado!T2:T100000,Detalle_facturado!A2:A100000,">="&AY17,Detalle_facturado!A2:A100000,"<"&AY17+1)) -> 2237074.6 | BC17: Claude Opus 4.7 | BD17: =SUMIF(Detalle_facturado!F2:F100000,BF17,Detalle_facturado!T2:T100000) -> 436.48961 | BE17: =SUMIF(Detalle_facturado!F2:F100000,BF17,Detalle_facturado!V2:V100000) -> 0 | BF17: Claude Opus 4.7 (Amazon Bedrock Edition) | BH17: =AO85 -> Base de datos | BI17: =SUMIF(Detalle_facturado!AB2:AB100000,BH17,Detalle_facturado!T2:T100000) -> 2873413.7 | BJ17: =SUMIF(Detalle_facturado!AB2:AB100000,BH17,Detalle_facturado!V2:V100000) -> 0 | BL17: =AS17 -> ADRES - PROD - Shared Resources | BM17: =IF(SUMIFS(Detalle_facturado!W2:W100000,Detalle_facturado!D2:D100000,BL17,Detalle_facturado!Q2:Q100000,"Procesamiento")=0,NA(),SUMIFS(Detalle_facturado!W2:W100000,Detalle_facturado!D2:D100000,BL17,Detalle_facturado!Q2:Q100000,"Procesamiento")) -> #N/A | BN17: =IF(SUMIFS(Detalle_facturado!W2:W100000,Detalle_facturado!D2:D100000,BL17,Detalle_facturado!Q2:Q100000,"Plataforma - Producción y Soporte")=0,NA(),SUMIFS(Detalle_facturado!W2:W100000,Detalle_facturado!D2:D100000,BL17,Detalle_facturado!Q2:Q100000,"Plataforma - Producción y Soporte")) -> 941534.9 | BO17: =IF(SUMIFS(Detalle_facturado!W2:W100000,Detalle_facturado!D2:D100000,BL17,Detalle_facturado!Q2:Q100000,"Plataforma - Ambiente de Pruebas")=0,NA(),SUMIFS(Detalle_facturado!W2:W100000,Detalle_facturado!D2:D100000,BL17,Detalle_facturado!Q2:Q100000,"Plataforma - Ambiente de Pruebas")) -> #N/A | BQ17: =AY17 -> 46232 | BR17: =SUMIFS(Detalle_facturado!T2:T100000,Detalle_facturado!A2:A100000,">="&BQ17,Detalle_facturado!A2:A100000,"<"&BQ17+1,Detalle_facturado!Q2:Q100000,"Procesamiento") -> 459723.95 | BS17: =SUMIFS(Detalle_facturado!T2:T100000,Detalle_facturado!A2:A100000,">="&BQ17,Detalle_facturado!A2:A100000,"<"&BQ17+1,Detalle_facturado!Q2:Q100000,"Plataforma - Producción y Soporte") -> 304430.69 | BT17: =SUMIFS(Detalle_facturado!T2:T100000,Detalle_facturado!A2:A100000,">="&BQ17,Detalle_facturado!A2:A100000,"<"&BQ17+1,Detalle_facturado!Q2:Q100000,"Plataforma - Ambiente de Pruebas") -> 1472920
X18: =+X16-X17 -> 225843750 | AA18: 0 | AD18: 0 | AK18: Amazon Bedrock | AL18: =SUMIF(Detalle_facturado!F2:F100000,AK18,Detalle_facturado!W2:W100000) -> 0.016265462 | AM18: =RANK(AL18,$AL$13:$AL$76,0)+COUNTIF($AL$13:AL18,AL18)-1 -> 60 | AO18: Storage | AP18: =SUMIF(Detalle_facturado!AB2:AB100000,AO18,Detalle_facturado!W2:W100000) -> 186615.91 | AQ18: =RANK(AP18,$AP$13:$AP$34,0)+COUNTIF($AP$13:AP18,AP18)-1 -> 12 | AS18: ADRES - PROD - Networking | AT18: =SUMIF(Detalle_facturado!D2:D100000,AS18,Detalle_facturado!W2:W100000) -> 796086.97 | AY18: =IF(AY17<INT(MAX(Detalle_facturado!A2:A100000)),AY17+1,NA()) -> 46233 | AZ18: =IF(ISNA(AY18),NA(),SUMIFS(Detalle_facturado!W2:W100000,Detalle_facturado!A2:A100000,">="&AY18,Detalle_facturado!A2:A100000,"<"&AY18+1)) -> 1306421.2 | BA18: =IF(ISNA(AY18),NA(),SUMIFS(Detalle_facturado!T2:T100000,Detalle_facturado!A2:A100000,">="&AY18,Detalle_facturado!A2:A100000,"<"&AY18+1)) -> 1306384.8 | BH18: =AO86 -> Operaciones y gestion | BI18: =SUMIF(Detalle_facturado!AB2:AB100000,BH18,Detalle_facturado!T2:T100000) -> 1725418.3 | BJ18: =SUMIF(Detalle_facturado!AB2:AB100000,BH18,Detalle_facturado!V2:V100000) -> 0 | BL18: =AS18 -> ADRES - PROD - Networking | BM18: =IF(SUMIFS(Detalle_facturado!W2:W100000,Detalle_facturado!D2:D100000,BL18,Detalle_facturado!Q2:Q100000,"Procesamiento")=0,NA(),SUMIFS(Detalle_facturado!W2:W100000,Detalle_facturado!D2:D100000,BL18,Detalle_facturado!Q2:Q100000,"Procesamiento")) -> #N/A | BN18: =IF(SUMIFS(Detalle_facturado!W2:W100000,Detalle_facturado!D2:D100000,BL18,Detalle_facturado!Q2:Q100000,"Plataforma - Producción y Soporte")=0,NA(),SUMIFS(Detalle_facturado!W2:W100000,Detalle_facturado!D2:D100000,BL18,Detalle_facturado!Q2:Q100000,"Plataforma - Producción y Soporte")) -> 796086.97 | BO18: =IF(SUMIFS(Detalle_facturado!W2:W100000,Detalle_facturado!D2:D100000,BL18,Detalle_facturado!Q2:Q100000,"Plataforma - Ambiente de Pruebas")=0,NA(),SUMIFS(Detalle_facturado!W2:W100000,Detalle_facturado!D2:D100000,BL18,Detalle_facturado!Q2:Q100000,"Plataforma - Ambiente de Pruebas")) -> #N/A | BQ18: =AY18 -> 46233 | BR18: =SUMIFS(Detalle_facturado!T2:T100000,Detalle_facturado!A2:A100000,">="&BQ18,Detalle_facturado!A2:A100000,"<"&BQ18+1,Detalle_facturado!Q2:Q100000,"Procesamiento") -> 47.866057 | BS18: =SUMIFS(Detalle_facturado!T2:T100000,Detalle_facturado!A2:A100000,">="&BQ18,Detalle_facturado!A2:A100000,"<"&BQ18+1,Detalle_facturado!Q2:Q100000,"Plataforma - Producción y Soporte") -> 306817.87 | BT18: =SUMIFS(Detalle_facturado!T2:T100000,Detalle_facturado!A2:A100000,">="&BQ18,Detalle_facturado!A2:A100000,"<"&BQ18+1,Detalle_facturado!Q2:Q100000,"Plataforma - Ambiente de Pruebas") -> 999519.05
W19: Creditos | X19: =+X18*35% -> 79045312 | AA19: =+AA18*35% -> 0 | AD19: =+AD18*35% -> 0 | AK19: Amazon Bedrock AgentCore | AL19: =SUMIF(Detalle_facturado!F2:F100000,AK19,Detalle_facturado!W2:W100000) -> 453629.13 | AM19: =RANK(AL19,$AL$13:$AL$76,0)+COUNTIF($AL$13:AL19,AL19)-1 -> 16 | AO19: DevOps | AP19: =SUMIF(Detalle_facturado!AB2:AB100000,AO19,Detalle_facturado!W2:W100000) -> 428349.9 | AQ19: =RANK(AP19,$AP$13:$AP$34,0)+COUNTIF($AP$13:AP19,AP19)-1 -> 11 | AS19: ADRES - PROD - Tooling | AT19: =SUMIF(Detalle_facturado!D2:D100000,AS19,Detalle_facturado!W2:W100000) -> 65891.646 | AY19: =IF(AY18<INT(MAX(Detalle_facturado!A2:A100000)),AY18+1,NA()) -> 46234 | AZ19: =IF(ISNA(AY19),NA(),SUMIFS(Detalle_facturado!W2:W100000,Detalle_facturado!A2:A100000,">="&AY19,Detalle_facturado!A2:A100000,"<"&AY19+1)) -> 1069543.8 | BA19: =IF(ISNA(AY19),NA(),SUMIFS(Detalle_facturado!T2:T100000,Detalle_facturado!A2:A100000,">="&AY19,Detalle_facturado!A2:A100000,"<"&AY19+1)) -> 1069507.7 | BH19: =AO87 -> Observabilidad | BI19: =SUMIF(Detalle_facturado!AB2:AB100000,BH19,Detalle_facturado!T2:T100000) -> 1644557 | BJ19: =SUMIF(Detalle_facturado!AB2:AB100000,BH19,Detalle_facturado!V2:V100000) -> 1.4913694 | BL19: =AS19 -> ADRES - PROD - Tooling | BM19: =IF(SUMIFS(Detalle_facturado!W2:W100000,Detalle_facturado!D2:D100000,BL19,Detalle_facturado!Q2:Q100000,"Procesamiento")=0,NA(),SUMIFS(Detalle_facturado!W2:W100000,Detalle_facturado!D2:D100000,BL19,Detalle_facturado!Q2:Q100000,"Procesamiento")) -> #N/A | BN19: =IF(SUMIFS(Detalle_facturado!W2:W100000,Detalle_facturado!D2:D100000,BL19,Detalle_facturado!Q2:Q100000,"Plataforma - Producción y Soporte")=0,NA(),SUMIFS(Detalle_facturado!W2:W100000,Detalle_facturado!D2:D100000,BL19,Detalle_facturado!Q2:Q100000,"Plataforma - Producción y Soporte")) -> 65891.646 | BO19: =IF(SUMIFS(Detalle_facturado!W2:W100000,Detalle_facturado!D2:D100000,BL19,Detalle_facturado!Q2:Q100000,"Plataforma - Ambiente de Pruebas")=0,NA(),SUMIFS(Detalle_facturado!W2:W100000,Detalle_facturado!D2:D100000,BL19,Detalle_facturado!Q2:Q100000,"Plataforma - Ambiente de Pruebas")) -> #N/A | BQ19: =AY19 -> 46234 | BR19: =SUMIFS(Detalle_facturado!T2:T100000,Detalle_facturado!A2:A100000,">="&BQ19,Detalle_facturado!A2:A100000,"<"&BQ19+1,Detalle_facturado!Q2:Q100000,"Procesamiento") -> 47.573785 | BS19: =SUMIFS(Detalle_facturado!T2:T100000,Detalle_facturado!A2:A100000,">="&BQ19,Detalle_facturado!A2:A100000,"<"&BQ19+1,Detalle_facturado!Q2:Q100000,"Plataforma - Producción y Soporte") -> 307605.07 | BT19: =SUMIFS(Detalle_facturado!T2:T100000,Detalle_facturado!A2:A100000,">="&BQ19,Detalle_facturado!A2:A100000,"<"&BQ19+1,Detalle_facturado!Q2:Q100000,"Plataforma - Ambiente de Pruebas") -> 761855.02
W20: valor a 3 meses | X20: =+X19/3 -> 26348438 | AA20: =+AA19/3 -> 0 | AD20: =+AD19/3 -> 0 | AK20: Amazon EC2 | AL20: =SUMIF(Detalle_facturado!F2:F100000,AK20,Detalle_facturado!W2:W100000) -> 5814352.4 | AM20: =RANK(AL20,$AL$13:$AL$76,0)+COUNTIF($AL$13:AL20,AL20)-1 -> 4 | AO20: Backup y resiliencia | AP20: =SUMIF(Detalle_facturado!AB2:AB100000,AO20,Detalle_facturado!W2:W100000) -> 113.62492 | AQ20: =RANK(AP20,$AP$13:$AP$34,0)+COUNTIF($AP$13:AP20,AP20)-1 -> 21 | AS20: ADRES - PROD - Logs Archive | AT20: =SUMIF(Detalle_facturado!D2:D100000,AS20,Detalle_facturado!W2:W100000) -> 444.53979 | AY20: =IF(AY19<INT(MAX(Detalle_facturado!A2:A100000)),AY19+1,NA()) -> 46235 | AZ20: =IF(ISNA(AY20),NA(),SUMIFS(Detalle_facturado!W2:W100000,Detalle_facturado!A2:A100000,">="&AY20,Detalle_facturado!A2:A100000,"<"&AY20+1)) -> 21798038 | BA20: =IF(ISNA(AY20),NA(),SUMIFS(Detalle_facturado!T2:T100000,Detalle_facturado!A2:A100000,">="&AY20,Detalle_facturado!A2:A100000,"<"&AY20+1)) -> 21798004 | BH20: =AO88 -> Seguridad | BI20: =SUMIF(Detalle_facturado!AB2:AB100000,BH20,Detalle_facturado!T2:T100000) -> 1559771.2 | BJ20: =SUMIF(Detalle_facturado!AB2:AB100000,BH20,Detalle_facturado!V2:V100000) -> 0 | BL20: =AS20 -> ADRES - PROD - Logs Archive | BM20: =IF(SUMIFS(Detalle_facturado!W2:W100000,Detalle_facturado!D2:D100000,BL20,Detalle_facturado!Q2:Q100000,"Procesamiento")=0,NA(),SUMIFS(Detalle_facturado!W2:W100000,Detalle_facturado!D2:D100000,BL20,Detalle_facturado!Q2:Q100000,"Procesamiento")) -> #N/A | BN20: =IF(SUMIFS(Detalle_facturado!W2:W100000,Detalle_facturado!D2:D100000,BL20,Detalle_facturado!Q2:Q100000,"Plataforma - Producción y Soporte")=0,NA(),SUMIFS(Detalle_facturado!W2:W100000,Detalle_facturado!D2:D100000,BL20,Detalle_facturado!Q2:Q100000,"Plataforma - Producción y Soporte")) -> 444.53979 | BO20: =IF(SUMIFS(Detalle_facturado!W2:W100000,Detalle_facturado!D2:D100000,BL20,Detalle_facturado!Q2:Q100000,"Plataforma - Ambiente de Pruebas")=0,NA(),SUMIFS(Detalle_facturado!W2:W100000,Detalle_facturado!D2:D100000,BL20,Detalle_facturado!Q2:Q100000,"Plataforma - Ambiente de Pruebas")) -> #N/A | BQ20: =AY20 -> 46235 | BR20: =SUMIFS(Detalle_facturado!T2:T100000,Detalle_facturado!A2:A100000,">="&BQ20,Detalle_facturado!A2:A100000,"<"&BQ20+1,Detalle_facturado!Q2:Q100000,"Procesamiento") -> 45.559377 | BS20: =SUMIFS(Detalle_facturado!T2:T100000,Detalle_facturado!A2:A100000,">="&BQ20,Detalle_facturado!A2:A100000,"<"&BQ20+1,Detalle_facturado!Q2:Q100000,"Plataforma - Producción y Soporte") -> 21167422 | BT20: =SUMIFS(Detalle_facturado!T2:T100000,Detalle_facturado!A2:A100000,">="&BQ20,Detalle_facturado!A2:A100000,"<"&BQ20+1,Detalle_facturado!Q2:Q100000,"Plataforma - Ambiente de Pruebas") -> 630536.39
AK21: Amazon ECS / Fargate | AL21: =SUMIF(Detalle_facturado!F2:F100000,AK21,Detalle_facturado!W2:W100000) -> 3462110.7 | AM21: =RANK(AL21,$AL$13:$AL$76,0)+COUNTIF($AL$13:AL21,AL21)-1 -> 5 | AO21: Analitica y BI | AP21: =SUMIF(Detalle_facturado!AB2:AB100000,AO21,Detalle_facturado!W2:W100000) -> 8397938.4 | AQ21: =RANK(AP21,$AP$13:$AP$34,0)+COUNTIF($AP$13:AP21,AP21)-1 -> 3 | AY21: =IF(AY20<INT(MAX(Detalle_facturado!A2:A100000)),AY20+1,NA()) -> 46236 | AZ21: =IF(ISNA(AY21),NA(),SUMIFS(Detalle_facturado!W2:W100000,Detalle_facturado!A2:A100000,">="&AY21,Detalle_facturado!A2:A100000,"<"&AY21+1)) -> 856858.1 | BA21: =IF(ISNA(AY21),NA(),SUMIFS(Detalle_facturado!T2:T100000,Detalle_facturado!A2:A100000,">="&AY21,Detalle_facturado!A2:A100000,"<"&AY21+1)) -> 856824.13 | BH21: =AO89 -> Networking | BI21: =SUMIF(Detalle_facturado!AB2:AB100000,BH21,Detalle_facturado!T2:T100000) -> 1404203.6 | BJ21: =SUMIF(Detalle_facturado!AB2:AB100000,BH21,Detalle_facturado!V2:V100000) -> 5.2434704 | BQ21: =AY21 -> 46236 | BR21: =SUMIFS(Detalle_facturado!T2:T100000,Detalle_facturado!A2:A100000,">="&BQ21,Detalle_facturado!A2:A100000,"<"&BQ21+1,Detalle_facturado!Q2:Q100000,"Procesamiento") -> 44.701672 | BS21: =SUMIFS(Detalle_facturado!T2:T100000,Detalle_facturado!A2:A100000,">="&BQ21,Detalle_facturado!A2:A100000,"<"&BQ21+1,Detalle_facturado!Q2:Q100000,"Plataforma - Producción y Soporte") -> 265368.19 | BT21: =SUMIFS(Detalle_facturado!T2:T100000,Detalle_facturado!A2:A100000,">="&BQ21,Detalle_facturado!A2:A100000,"<"&BQ21+1,Detalle_facturado!Q2:Q100000,"Plataforma - Ambiente de Pruebas") -> 591411.24
AK22: AWS Lambda | AL22: =SUMIF(Detalle_facturado!F2:F100000,AK22,Detalle_facturado!W2:W100000) -> 115221.43 | AM22: =RANK(AL22,$AL$13:$AL$76,0)+COUNTIF($AL$13:AL22,AL22)-1 -> 25 | AO22: Gobierno de datos | AP22: =SUMIF(Detalle_facturado!AB2:AB100000,AO22,Detalle_facturado!W2:W100000) -> 1814.6941 | AQ22: =RANK(AP22,$AP$13:$AP$34,0)+COUNTIF($AP$13:AP22,AP22)-1 -> 19 | AY22: =IF(AY21<INT(MAX(Detalle_facturado!A2:A100000)),AY21+1,NA()) -> 46237 | AZ22: =IF(ISNA(AY22),NA(),SUMIFS(Detalle_facturado!W2:W100000,Detalle_facturado!A2:A100000,">="&AY22,Detalle_facturado!A2:A100000,"<"&AY22+1)) -> 1116258.8 | BA22: =IF(ISNA(AY22),NA(),SUMIFS(Detalle_facturado!T2:T100000,Detalle_facturado!A2:A100000,">="&AY22,Detalle_facturado!A2:A100000,"<"&AY22+1)) -> 1116223.5 | BH22: =AO90 -> Gobierno y cumplimiento | BI22: =SUMIF(Detalle_facturado!AB2:AB100000,BH22,Detalle_facturado!T2:T100000) -> 1029176.1 | BJ22: =SUMIF(Detalle_facturado!AB2:AB100000,BH22,Detalle_facturado!V2:V100000) -> 0 | BQ22: =AY22 -> 46237 | BR22: =SUMIFS(Detalle_facturado!T2:T100000,Detalle_facturado!A2:A100000,">="&BQ22,Detalle_facturado!A2:A100000,"<"&BQ22+1,Detalle_facturado!Q2:Q100000,"Procesamiento") -> 46.390443 | BS22: =SUMIFS(Detalle_facturado!T2:T100000,Detalle_facturado!A2:A100000,">="&BQ22,Detalle_facturado!A2:A100000,"<"&BQ22+1,Detalle_facturado!Q2:Q100000,"Plataforma - Producción y Soporte") -> 297980.16 | BT22: =SUMIFS(Detalle_facturado!T2:T100000,Detalle_facturado!A2:A100000,">="&BQ22,Detalle_facturado!A2:A100000,"<"&BQ22+1,Detalle_facturado!Q2:Q100000,"Plataforma - Ambiente de Pruebas") -> 818196.95
AK23: Amazon SageMaker | AL23: =SUMIF(Detalle_facturado!F2:F100000,AK23,Detalle_facturado!W2:W100000) -> 7183.9221 | AM23: =RANK(AL23,$AL$13:$AL$76,0)+COUNTIF($AL$13:AL23,AL23)-1 -> 36 | AO23: Integracion y mensajeria | AP23: =SUMIF(Detalle_facturado!AB2:AB100000,AO23,Detalle_facturado!W2:W100000) -> 122977.64 | AQ23: =RANK(AP23,$AP$13:$AP$34,0)+COUNTIF($AP$13:AP23,AP23)-1 -> 14 | AY23: =IF(AY22<INT(MAX(Detalle_facturado!A2:A100000)),AY22+1,NA()) -> 46238 | AZ23: =IF(ISNA(AY23),NA(),SUMIFS(Detalle_facturado!W2:W100000,Detalle_facturado!A2:A100000,">="&AY23,Detalle_facturado!A2:A100000,"<"&AY23+1)) -> 3003591.6 | BA23: =IF(ISNA(AY23),NA(),SUMIFS(Detalle_facturado!T2:T100000,Detalle_facturado!A2:A100000,">="&AY23,Detalle_facturado!A2:A100000,"<"&AY23+1)) -> 3003554.7 | BQ23: =AY23 -> 46238 | BR23: =SUMIFS(Detalle_facturado!T2:T100000,Detalle_facturado!A2:A100000,">="&BQ23,Detalle_facturado!A2:A100000,"<"&BQ23+1,Detalle_facturado!Q2:Q100000,"Procesamiento") -> 48.484369 | BS23: =SUMIFS(Detalle_facturado!T2:T100000,Detalle_facturado!A2:A100000,">="&BQ23,Detalle_facturado!A2:A100000,"<"&BQ23+1,Detalle_facturado!Q2:Q100000,"Plataforma - Producción y Soporte") -> 286854.63 | BT23: =SUMIFS(Detalle_facturado!T2:T100000,Detalle_facturado!A2:A100000,">="&BQ23,Detalle_facturado!A2:A100000,"<"&BQ23+1,Detalle_facturado!Q2:Q100000,"Plataforma - Ambiente de Pruebas") -> 2716651.6
AK24: Amazon RDS | AL24: =SUMIF(Detalle_facturado!F2:F100000,AK24,Detalle_facturado!W2:W100000) -> 2663512.3 | AM24: =RANK(AL24,$AL$13:$AL$76,0)+COUNTIF($AL$13:AL24,AL24)-1 -> 7 | AO24: Integracion y orquestacion | AP24: =SUMIF(Detalle_facturado!AB2:AB100000,AO24,Detalle_facturado!W2:W100000) -> 23076.299 | AQ24: =RANK(AP24,$AP$13:$AP$34,0)+COUNTIF($AP$13:AP24,AP24)-1 -> 17 | AY24: =IF(AY23<INT(MAX(Detalle_facturado!A2:A100000)),AY23+1,NA()) -> 46239 | AZ24: =IF(ISNA(AY24),NA(),SUMIFS(Detalle_facturado!W2:W100000,Detalle_facturado!A2:A100000,">="&AY24,Detalle_facturado!A2:A100000,"<"&AY24+1)) -> 1874773.2 | BA24: =IF(ISNA(AY24),NA(),SUMIFS(Detalle_facturado!T2:T100000,Detalle_facturado!A2:A100000,">="&AY24,Detalle_facturado!A2:A100000,"<"&AY24+1)) -> 1874739.7 | BQ24: =AY24 -> 46239 | BR24: =SUMIFS(Detalle_facturado!T2:T100000,Detalle_facturado!A2:A100000,">="&BQ24,Detalle_facturado!A2:A100000,"<"&BQ24+1,Detalle_facturado!Q2:Q100000,"Procesamiento") -> 44.017176 | BS24: =SUMIFS(Detalle_facturado!T2:T100000,Detalle_facturado!A2:A100000,">="&BQ24,Detalle_facturado!A2:A100000,"<"&BQ24+1,Detalle_facturado!Q2:Q100000,"Plataforma - Producción y Soporte") -> 291381.25 | BT24: =SUMIFS(Detalle_facturado!T2:T100000,Detalle_facturado!A2:A100000,">="&BQ24,Detalle_facturado!A2:A100000,"<"&BQ24+1,Detalle_facturado!Q2:Q100000,"Plataforma - Ambiente de Pruebas") -> 1583314.5
AK25: Amazon DynamoDB | AL25: =SUMIF(Detalle_facturado!F2:F100000,AK25,Detalle_facturado!W2:W100000) -> 209901.42 | AM25: =RANK(AL25,$AL$13:$AL$76,0)+COUNTIF($AL$13:AL25,AL25)-1 -> 18 | AO25: Networking | AP25: =SUMIF(Detalle_facturado!AB2:AB100000,AO25,Detalle_facturado!W2:W100000) -> 1404208.8 | AQ25: =RANK(AP25,$AP$13:$AP$34,0)+COUNTIF($AP$13:AP25,AP25)-1 -> 9 | AY25: =IF(AY24<INT(MAX(Detalle_facturado!A2:A100000)),AY24+1,NA()) -> 46240 | AZ25: =IF(ISNA(AY25),NA(),SUMIFS(Detalle_facturado!W2:W100000,Detalle_facturado!A2:A100000,">="&AY25,Detalle_facturado!A2:A100000,"<"&AY25+1)) -> 1624977.1 | BA25: =IF(ISNA(AY25),NA(),SUMIFS(Detalle_facturado!T2:T100000,Detalle_facturado!A2:A100000,">="&AY25,Detalle_facturado!A2:A100000,"<"&AY25+1)) -> 1624967.8 | BQ25: =AY25 -> 46240 | BR25: =SUMIFS(Detalle_facturado!T2:T100000,Detalle_facturado!A2:A100000,">="&BQ25,Detalle_facturado!A2:A100000,"<"&BQ25+1,Detalle_facturado!Q2:Q100000,"Procesamiento") -> 12.302546 | BS25: =SUMIFS(Detalle_facturado!T2:T100000,Detalle_facturado!A2:A100000,">="&BQ25,Detalle_facturado!A2:A100000,"<"&BQ25+1,Detalle_facturado!Q2:Q100000,"Plataforma - Producción y Soporte") -> 260690 | BT25: =SUMIFS(Detalle_facturado!T2:T100000,Detalle_facturado!A2:A100000,">="&BQ25,Detalle_facturado!A2:A100000,"<"&BQ25+1,Detalle_facturado!Q2:Q100000,"Plataforma - Ambiente de Pruebas") -> 1364265.4
AK26: Amazon OpenSearch Service | AL26: =SUMIF(Detalle_facturado!F2:F100000,AK26,Detalle_facturado!W2:W100000) -> 3371362.2 | AM26: =RANK(AL26,$AL$13:$AL$76,0)+COUNTIF($AL$13:AL26,AL26)-1 -> 6 | AO26: Seguridad | AP26: =SUMIF(Detalle_facturado!AB2:AB100000,AO26,Detalle_facturado!W2:W100000) -> 1559771.2 | AQ26: =RANK(AP26,$AP$13:$AP$34,0)+COUNTIF($AP$13:AP26,AP26)-1 -> 8 | AY26: =IF(AY25<INT(MAX(Detalle_facturado!A2:A100000)),AY25+1,NA()) -> 46241 | AZ26: =IF(ISNA(AY26),NA(),SUMIFS(Detalle_facturado!W2:W100000,Detalle_facturado!A2:A100000,">="&AY26,Detalle_facturado!A2:A100000,"<"&AY26+1)) -> 837758.62 | BA26: =IF(ISNA(AY26),NA(),SUMIFS(Detalle_facturado!T2:T100000,Detalle_facturado!A2:A100000,">="&AY26,Detalle_facturado!A2:A100000,"<"&AY26+1)) -> 837758.62 | BQ26: =AY26 -> 46241 | BR26: =SUMIFS(Detalle_facturado!T2:T100000,Detalle_facturado!A2:A100000,">="&BQ26,Detalle_facturado!A2:A100000,"<"&BQ26+1,Detalle_facturado!Q2:Q100000,"Procesamiento") -> 0 | BS26: =SUMIFS(Detalle_facturado!T2:T100000,Detalle_facturado!A2:A100000,">="&BQ26,Detalle_facturado!A2:A100000,"<"&BQ26+1,Detalle_facturado!Q2:Q100000,"Plataforma - Producción y Soporte") -> 257023.72 | BT26: =SUMIFS(Detalle_facturado!T2:T100000,Detalle_facturado!A2:A100000,">="&BQ26,Detalle_facturado!A2:A100000,"<"&BQ26+1,Detalle_facturado!Q2:Q100000,"Plataforma - Ambiente de Pruebas") -> 580734.9
AK27: Amazon S3 | AL27: =SUMIF(Detalle_facturado!F2:F100000,AK27,Detalle_facturado!W2:W100000) -> 186615.91 | AM27: =RANK(AL27,$AL$13:$AL$76,0)+COUNTIF($AL$13:AL27,AL27)-1 -> 19 | AO27: Observabilidad | AP27: =SUMIF(Detalle_facturado!AB2:AB100000,AO27,Detalle_facturado!W2:W100000) -> 1644558.5 | AQ27: =RANK(AP27,$AP$13:$AP$34,0)+COUNTIF($AP$13:AP27,AP27)-1 -> 7 | AY27: =IF(AY26<INT(MAX(Detalle_facturado!A2:A100000)),AY26+1,NA()) -> 46242 | AZ27: =IF(ISNA(AY27),NA(),SUMIFS(Detalle_facturado!W2:W100000,Detalle_facturado!A2:A100000,">="&AY27,Detalle_facturado!A2:A100000,"<"&AY27+1)) -> 837279.59 | BA27: =IF(ISNA(AY27),NA(),SUMIFS(Detalle_facturado!T2:T100000,Detalle_facturado!A2:A100000,">="&AY27,Detalle_facturado!A2:A100000,"<"&AY27+1)) -> 837279.59 | BQ27: =AY27 -> 46242 | BR27: =SUMIFS(Detalle_facturado!T2:T100000,Detalle_facturado!A2:A100000,">="&BQ27,Detalle_facturado!A2:A100000,"<"&BQ27+1,Detalle_facturado!Q2:Q100000,"Procesamiento") -> 0 | BS27: =SUMIFS(Detalle_facturado!T2:T100000,Detalle_facturado!A2:A100000,">="&BQ27,Detalle_facturado!A2:A100000,"<"&BQ27+1,Detalle_facturado!Q2:Q100000,"Plataforma - Producción y Soporte") -> 256758.43 | BT27: =SUMIFS(Detalle_facturado!T2:T100000,Detalle_facturado!A2:A100000,">="&BQ27,Detalle_facturado!A2:A100000,"<"&BQ27+1,Detalle_facturado!Q2:Q100000,"Plataforma - Ambiente de Pruebas") -> 580521.16
AK28: Amazon ECR | AL28: =SUMIF(Detalle_facturado!F2:F100000,AK28,Detalle_facturado!W2:W100000) -> 111734.09 | AM28: =RANK(AL28,$AL$13:$AL$76,0)+COUNTIF($AL$13:AL28,AL28)-1 -> 27 | AO28: Gobierno y cumplimiento | AP28: =SUMIF(Detalle_facturado!AB2:AB100000,AO28,Detalle_facturado!W2:W100000) -> 1029176.1 | AQ28: =RANK(AP28,$AP$13:$AP$34,0)+COUNTIF($AP$13:AP28,AP28)-1 -> 10 | AY28: =IF(AY27<INT(MAX(Detalle_facturado!A2:A100000)),AY27+1,NA()) -> 46243 | AZ28: =IF(ISNA(AY28),NA(),SUMIFS(Detalle_facturado!W2:W100000,Detalle_facturado!A2:A100000,">="&AY28,Detalle_facturado!A2:A100000,"<"&AY28+1)) -> 839204.97 | BA28: =IF(ISNA(AY28),NA(),SUMIFS(Detalle_facturado!T2:T100000,Detalle_facturado!A2:A100000,">="&AY28,Detalle_facturado!A2:A100000,"<"&AY28+1)) -> 839204.97 | BQ28: =AY28 -> 46243 | BR28: =SUMIFS(Detalle_facturado!T2:T100000,Detalle_facturado!A2:A100000,">="&BQ28,Detalle_facturado!A2:A100000,"<"&BQ28+1,Detalle_facturado!Q2:Q100000,"Procesamiento") -> 0 | BS28: =SUMIFS(Detalle_facturado!T2:T100000,Detalle_facturado!A2:A100000,">="&BQ28,Detalle_facturado!A2:A100000,"<"&BQ28+1,Detalle_facturado!Q2:Q100000,"Plataforma - Producción y Soporte") -> 257826.92 | BT28: =SUMIFS(Detalle_facturado!T2:T100000,Detalle_facturado!A2:A100000,">="&BQ28,Detalle_facturado!A2:A100000,"<"&BQ28+1,Detalle_facturado!Q2:Q100000,"Plataforma - Ambiente de Pruebas") -> 581378.04
AK29: AWS Backup | AL29: =SUMIF(Detalle_facturado!F2:F100000,AK29,Detalle_facturado!W2:W100000) -> 113.62492 | AM29: =RANK(AL29,$AL$13:$AL$76,0)+COUNTIF($AL$13:AL29,AL29)-1 -> 51 | AO29: Operaciones y gestion | AP29: =SUMIF(Detalle_facturado!AB2:AB100000,AO29,Detalle_facturado!W2:W100000) -> 1725418.3 | AQ29: =RANK(AP29,$AP$13:$AP$34,0)+COUNTIF($AP$13:AP29,AP29)-1 -> 6 | AY29: =IF(AY28<INT(MAX(Detalle_facturado!A2:A100000)),AY28+1,NA()) -> 46244 | AZ29: =IF(ISNA(AY29),NA(),SUMIFS(Detalle_facturado!W2:W100000,Detalle_facturado!A2:A100000,">="&AY29,Detalle_facturado!A2:A100000,"<"&AY29+1)) -> 1024494 | BA29: =IF(ISNA(AY29),NA(),SUMIFS(Detalle_facturado!T2:T100000,Detalle_facturado!A2:A100000,">="&AY29,Detalle_facturado!A2:A100000,"<"&AY29+1)) -> 953976.53 | BQ29: =AY29 -> 46244 | BR29: =SUMIFS(Detalle_facturado!T2:T100000,Detalle_facturado!A2:A100000,">="&BQ29,Detalle_facturado!A2:A100000,"<"&BQ29+1,Detalle_facturado!Q2:Q100000,"Procesamiento") -> 92786.215 | BS29: =SUMIFS(Detalle_facturado!T2:T100000,Detalle_facturado!A2:A100000,">="&BQ29,Detalle_facturado!A2:A100000,"<"&BQ29+1,Detalle_facturado!Q2:Q100000,"Plataforma - Producción y Soporte") -> 260083.98 | BT29: =SUMIFS(Detalle_facturado!T2:T100000,Detalle_facturado!A2:A100000,">="&BQ29,Detalle_facturado!A2:A100000,"<"&BQ29+1,Detalle_facturado!Q2:Q100000,"Plataforma - Ambiente de Pruebas") -> 601106.33
AK30: Amazon QuickSight | AL30: =SUMIF(Detalle_facturado!F2:F100000,AK30,Detalle_facturado!W2:W100000) -> 8349505.4 | AM30: =RANK(AL30,$AL$13:$AL$76,0)+COUNTIF($AL$13:AL30,AL30)-1 -> 3 | AO30: FinOps | AP30: =SUMIF(Detalle_facturado!AB2:AB100000,AO30,Detalle_facturado!W2:W100000) -> 31682.547 | AQ30: =RANK(AP30,$AP$13:$AP$34,0)+COUNTIF($AP$13:AP30,AP30)-1 -> 16 | AY30: =IF(AY29<INT(MAX(Detalle_facturado!A2:A100000)),AY29+1,NA()) -> 46245 | AZ30: =IF(ISNA(AY30),NA(),SUMIFS(Detalle_facturado!W2:W100000,Detalle_facturado!A2:A100000,">="&AY30,Detalle_facturado!A2:A100000,"<"&AY30+1)) -> 14241326 | BA30: =IF(ISNA(AY30),NA(),SUMIFS(Detalle_facturado!T2:T100000,Detalle_facturado!A2:A100000,">="&AY30,Detalle_facturado!A2:A100000,"<"&AY30+1)) -> 8624500.1 | BQ30: =AY30 -> 46245 | BR30: =SUMIFS(Detalle_facturado!T2:T100000,Detalle_facturado!A2:A100000,">="&BQ30,Detalle_facturado!A2:A100000,"<"&BQ30+1,Detalle_facturado!Q2:Q100000,"Procesamiento") -> 7390560.1 | BS30: =SUMIFS(Detalle_facturado!T2:T100000,Detalle_facturado!A2:A100000,">="&BQ30,Detalle_facturado!A2:A100000,"<"&BQ30+1,Detalle_facturado!Q2:Q100000,"Plataforma - Producción y Soporte") -> 501263.42 | BT30: =SUMIFS(Detalle_facturado!T2:T100000,Detalle_facturado!A2:A100000,">="&BQ30,Detalle_facturado!A2:A100000,"<"&BQ30+1,Detalle_facturado!Q2:Q100000,"Plataforma - Ambiente de Pruebas") -> 732676.54
AK31: Amazon Athena | AL31: =SUMIF(Detalle_facturado!F2:F100000,AK31,Detalle_facturado!W2:W100000) -> 3785.2289 | AM31: =RANK(AL31,$AL$13:$AL$76,0)+COUNTIF($AL$13:AL31,AL31)-1 -> 39 | AO31: Productividad de desarrollo | AP31: =SUMIF(Detalle_facturado!AB2:AB100000,AO31,Detalle_facturado!W2:W100000) -> 132056.07 | AQ31: =RANK(AP31,$AP$13:$AP$34,0)+COUNTIF($AP$13:AP31,AP31)-1 -> 13 | AY31: =IF(AY30<INT(MAX(Detalle_facturado!A2:A100000)),AY30+1,NA()) -> 46246 | AZ31: =IF(ISNA(AY31),NA(),SUMIFS(Detalle_facturado!W2:W100000,Detalle_facturado!A2:A100000,">="&AY31,Detalle_facturado!A2:A100000,"<"&AY31+1)) -> 2517428.6 | BA31: =IF(ISNA(AY31),NA(),SUMIFS(Detalle_facturado!T2:T100000,Detalle_facturado!A2:A100000,">="&AY31,Detalle_facturado!A2:A100000,"<"&AY31+1)) -> 1851121.4 | BQ31: =AY31 -> 46246 | BR31: =SUMIFS(Detalle_facturado!T2:T100000,Detalle_facturado!A2:A100000,">="&BQ31,Detalle_facturado!A2:A100000,"<"&BQ31+1,Detalle_facturado!Q2:Q100000,"Procesamiento") -> 876719.94 | BS31: =SUMIFS(Detalle_facturado!T2:T100000,Detalle_facturado!A2:A100000,">="&BQ31,Detalle_facturado!A2:A100000,"<"&BQ31+1,Detalle_facturado!Q2:Q100000,"Plataforma - Producción y Soporte") -> 274913.56 | BT31: =SUMIFS(Detalle_facturado!T2:T100000,Detalle_facturado!A2:A100000,">="&BQ31,Detalle_facturado!A2:A100000,"<"&BQ31+1,Detalle_facturado!Q2:Q100000,"Plataforma - Ambiente de Pruebas") -> 699487.95
AK32: AWS Glue | AL32: =SUMIF(Detalle_facturado!F2:F100000,AK32,Detalle_facturado!W2:W100000) -> 44647.764 | AM32: =RANK(AL32,$AL$13:$AL$76,0)+COUNTIF($AL$13:AL32,AL32)-1 -> 31 | AO32: Comunicaciones | AP32: =SUMIF(Detalle_facturado!AB2:AB100000,AO32,Detalle_facturado!W2:W100000) -> 452.95642 | AQ32: =RANK(AP32,$AP$13:$AP$34,0)+COUNTIF($AP$13:AP32,AP32)-1 -> 20 | AY32: =IF(AY31<INT(MAX(Detalle_facturado!A2:A100000)),AY31+1,NA()) -> 46247 | AZ32: =IF(ISNA(AY32),NA(),SUMIFS(Detalle_facturado!W2:W100000,Detalle_facturado!A2:A100000,">="&AY32,Detalle_facturado!A2:A100000,"<"&AY32+1)) -> 1405042.3 | BA32: =IF(ISNA(AY32),NA(),SUMIFS(Detalle_facturado!T2:T100000,Detalle_facturado!A2:A100000,">="&AY32,Detalle_facturado!A2:A100000,"<"&AY32+1)) -> 1368924.1 | BQ32: =AY32 -> 46247 | BR32: =SUMIFS(Detalle_facturado!T2:T100000,Detalle_facturado!A2:A100000,">="&BQ32,Detalle_facturado!A2:A100000,"<"&BQ32+1,Detalle_facturado!Q2:Q100000,"Procesamiento") -> 47523.963 | BS32: =SUMIFS(Detalle_facturado!T2:T100000,Detalle_facturado!A2:A100000,">="&BQ32,Detalle_facturado!A2:A100000,"<"&BQ32+1,Detalle_facturado!Q2:Q100000,"Plataforma - Producción y Soporte") -> 725140.84 | BT32: =SUMIFS(Detalle_facturado!T2:T100000,Detalle_facturado!A2:A100000,">="&BQ32,Detalle_facturado!A2:A100000,"<"&BQ32+1,Detalle_facturado!Q2:Q100000,"Plataforma - Ambiente de Pruebas") -> 596259.3
AK33: Amazon DataZone | AL33: =SUMIF(Detalle_facturado!F2:F100000,AK33,Detalle_facturado!W2:W100000) -> 1814.6941 | AM33: =RANK(AL33,$AL$13:$AL$76,0)+COUNTIF($AL$13:AL33,AL33)-1 -> 43 | AO33: Soporte AWS | AP33: =SUMIF(Detalle_facturado!AB2:AB100000,AO33,Detalle_facturado!W2:W100000) -> 20895270 | AQ33: =RANK(AP33,$AP$13:$AP$34,0)+COUNTIF($AP$13:AP33,AP33)-1 -> 2 | AY33: =IF(AY32<INT(MAX(Detalle_facturado!A2:A100000)),AY32+1,NA()) -> 46248 | AZ33: =IF(ISNA(AY33),NA(),SUMIFS(Detalle_facturado!W2:W100000,Detalle_facturado!A2:A100000,">="&AY33,Detalle_facturado!A2:A100000,"<"&AY33+1)) -> 70049349 | BA33: =IF(ISNA(AY33),NA(),SUMIFS(Detalle_facturado!T2:T100000,Detalle_facturado!A2:A100000,">="&AY33,Detalle_facturado!A2:A100000,"<"&AY33+1)) -> 40413287 | BQ33: =AY33 -> 46248 | BR33: =SUMIFS(Detalle_facturado!T2:T100000,Detalle_facturado!A2:A100000,">="&BQ33,Detalle_facturado!A2:A100000,"<"&BQ33+1,Detalle_facturado!Q2:Q100000,"Procesamiento") -> 38994820 | BS33: =SUMIFS(Detalle_facturado!T2:T100000,Detalle_facturado!A2:A100000,">="&BQ33,Detalle_facturado!A2:A100000,"<"&BQ33+1,Detalle_facturado!Q2:Q100000,"Plataforma - Producción y Soporte") -> 827503.17 | BT33: =SUMIFS(Detalle_facturado!T2:T100000,Detalle_facturado!A2:A100000,">="&BQ33,Detalle_facturado!A2:A100000,"<"&BQ33+1,Detalle_facturado!Q2:Q100000,"Plataforma - Ambiente de Pruebas") -> 590963.85
AK34: Amazon Kinesis | AL34: =SUMIF(Detalle_facturado!F2:F100000,AK34,Detalle_facturado!W2:W100000) -> 119304.42 | AM34: =RANK(AL34,$AL$13:$AL$76,0)+COUNTIF($AL$13:AL34,AL34)-1 -> 24 | AO34: Marketplace y software de terceros | AP34: =SUMIF(Detalle_facturado!AB2:AB100000,AO34,Detalle_facturado!W2:W100000) -> 59652.211 | AQ34: =RANK(AP34,$AP$13:$AP$34,0)+COUNTIF($AP$13:AP34,AP34)-1 -> 15 | AY34: =IF(AY33<INT(MAX(Detalle_facturado!A2:A100000)),AY33+1,NA()) -> 46249 | AZ34: =IF(ISNA(AY34),NA(),SUMIFS(Detalle_facturado!W2:W100000,Detalle_facturado!A2:A100000,">="&AY34,Detalle_facturado!A2:A100000,"<"&AY34+1)) -> 836458.36 | BA34: =IF(ISNA(AY34),NA(),SUMIFS(Detalle_facturado!T2:T100000,Detalle_facturado!A2:A100000,">="&AY34,Detalle_facturado!A2:A100000,"<"&AY34+1)) -> 836458.36 | BQ34: =AY34 -> 46249 | BR34: =SUMIFS(Detalle_facturado!T2:T100000,Detalle_facturado!A2:A100000,">="&BQ34,Detalle_facturado!A2:A100000,"<"&BQ34+1,Detalle_facturado!Q2:Q100000,"Procesamiento") -> 0 | BS34: =SUMIFS(Detalle_facturado!T2:T100000,Detalle_facturado!A2:A100000,">="&BQ34,Detalle_facturado!A2:A100000,"<"&BQ34+1,Detalle_facturado!Q2:Q100000,"Plataforma - Producción y Soporte") -> 291484.63 | BT34: =SUMIFS(Detalle_facturado!T2:T100000,Detalle_facturado!A2:A100000,">="&BQ34,Detalle_facturado!A2:A100000,"<"&BQ34+1,Detalle_facturado!Q2:Q100000,"Plataforma - Ambiente de Pruebas") -> 544973.74
AK35: Amazon SQS | AL35: =SUMIF(Detalle_facturado!F2:F100000,AK35,Detalle_facturado!W2:W100000) -> 3673.2165 | AM35: =RANK(AL35,$AL$13:$AL$76,0)+COUNTIF($AL$13:AL35,AL35)-1 -> 40 | AY35: =IF(AY34<INT(MAX(Detalle_facturado!A2:A100000)),AY34+1,NA()) -> 46250 | AZ35: =IF(ISNA(AY35),NA(),SUMIFS(Detalle_facturado!W2:W100000,Detalle_facturado!A2:A100000,">="&AY35,Detalle_facturado!A2:A100000,"<"&AY35+1)) -> 3927624 | BA35: =IF(ISNA(AY35),NA(),SUMIFS(Detalle_facturado!T2:T100000,Detalle_facturado!A2:A100000,">="&AY35,Detalle_facturado!A2:A100000,"<"&AY35+1)) -> 2642018.1 | BQ35: =AY35 -> 46250 | BR35: =SUMIFS(Detalle_facturado!T2:T100000,Detalle_facturado!A2:A100000,">="&BQ35,Detalle_facturado!A2:A100000,"<"&BQ35+1,Detalle_facturado!Q2:Q100000,"Procesamiento") -> 1691586.8 | BS35: =SUMIFS(Detalle_facturado!T2:T100000,Detalle_facturado!A2:A100000,">="&BQ35,Detalle_facturado!A2:A100000,"<"&BQ35+1,Detalle_facturado!Q2:Q100000,"Plataforma - Producción y Soporte") -> 405638.53 | BT35: =SUMIFS(Detalle_facturado!T2:T100000,Detalle_facturado!A2:A100000,">="&BQ35,Detalle_facturado!A2:A100000,"<"&BQ35+1,Detalle_facturado!Q2:Q100000,"Plataforma - Ambiente de Pruebas") -> 544792.8
AK36: AWS Step Functions | AL36: =SUMIF(Detalle_facturado!F2:F100000,AK36,Detalle_facturado!W2:W100000) -> 23076.29 | AM36: =RANK(AL36,$AL$13:$AL$76,0)+COUNTIF($AL$13:AL36,AL36)-1 -> 33 | AY36: =IF(AY35<INT(MAX(Detalle_facturado!A2:A100000)),AY35+1,NA()) -> 46251 | AZ36: =IF(ISNA(AY36),NA(),SUMIFS(Detalle_facturado!W2:W100000,Detalle_facturado!A2:A100000,">="&AY36,Detalle_facturado!A2:A100000,"<"&AY36+1)) -> 912496.39 | BA36: =IF(ISNA(AY36),NA(),SUMIFS(Detalle_facturado!T2:T100000,Detalle_facturado!A2:A100000,">="&AY36,Detalle_facturado!A2:A100000,"<"&AY36+1)) -> 895879.87 | BQ36: =AY36 -> 46251 | BR36: =SUMIFS(Detalle_facturado!T2:T100000,Detalle_facturado!A2:A100000,">="&BQ36,Detalle_facturado!A2:A100000,"<"&BQ36+1,Detalle_facturado!Q2:Q100000,"Procesamiento") -> 21863.843 | BS36: =SUMIFS(Detalle_facturado!T2:T100000,Detalle_facturado!A2:A100000,">="&BQ36,Detalle_facturado!A2:A100000,"<"&BQ36+1,Detalle_facturado!Q2:Q100000,"Plataforma - Producción y Soporte") -> 329595.16 | BT36: =SUMIFS(Detalle_facturado!T2:T100000,Detalle_facturado!A2:A100000,">="&BQ36,Detalle_facturado!A2:A100000,"<"&BQ36+1,Detalle_facturado!Q2:Q100000,"Plataforma - Ambiente de Pruebas") -> 544420.86
AK37: AWSEvents | AL37: =SUMIF(Detalle_facturado!F2:F100000,AK37,Detalle_facturado!W2:W100000) -> 0.008772384 | AM37: =RANK(AL37,$AL$13:$AL$76,0)+COUNTIF($AL$13:AL37,AL37)-1 -> 62 | AY37: =IF(AY36<INT(MAX(Detalle_facturado!A2:A100000)),AY36+1,NA()) -> 46252 | AZ37: =IF(ISNA(AY37),NA(),SUMIFS(Detalle_facturado!W2:W100000,Detalle_facturado!A2:A100000,">="&AY37,Detalle_facturado!A2:A100000,"<"&AY37+1)) -> 892746.1 | BA37: =IF(ISNA(AY37),NA(),SUMIFS(Detalle_facturado!T2:T100000,Detalle_facturado!A2:A100000,">="&AY37,Detalle_facturado!A2:A100000,"<"&AY37+1)) -> 892746.1 | BQ37: =AY37 -> 46252 | BR37: =SUMIFS(Detalle_facturado!T2:T100000,Detalle_facturado!A2:A100000,">="&BQ37,Detalle_facturado!A2:A100000,"<"&BQ37+1,Detalle_facturado!Q2:Q100000,"Procesamiento") -> 0 | BS37: =SUMIFS(Detalle_facturado!T2:T100000,Detalle_facturado!A2:A100000,">="&BQ37,Detalle_facturado!A2:A100000,"<"&BQ37+1,Detalle_facturado!Q2:Q100000,"Plataforma - Producción y Soporte") -> 343380.74 | BT37: =SUMIFS(Detalle_facturado!T2:T100000,Detalle_facturado!A2:A100000,">="&BQ37,Detalle_facturado!A2:A100000,"<"&BQ37+1,Detalle_facturado!Q2:Q100000,"Plataforma - Ambiente de Pruebas") -> 549365.35
AK38: Amazon API Gateway | AL38: =SUMIF(Detalle_facturado!F2:F100000,AK38,Detalle_facturado!W2:W100000) -> 3262.1499 | AM38: =RANK(AL38,$AL$13:$AL$76,0)+COUNTIF($AL$13:AL38,AL38)-1 -> 41 | AY38: =IF(AY37<INT(MAX(Detalle_facturado!A2:A100000)),AY37+1,NA()) -> 46253 | AZ38: =IF(ISNA(AY38),NA(),SUMIFS(Detalle_facturado!W2:W100000,Detalle_facturado!A2:A100000,">="&AY38,Detalle_facturado!A2:A100000,"<"&AY38+1)) -> 882576.39 | BA38: =IF(ISNA(AY38),NA(),SUMIFS(Detalle_facturado!T2:T100000,Detalle_facturado!A2:A100000,">="&AY38,Detalle_facturado!A2:A100000,"<"&AY38+1)) -> 882576.39 | BQ38: =AY38 -> 46253 | BR38: =SUMIFS(Detalle_facturado!T2:T100000,Detalle_facturado!A2:A100000,">="&BQ38,Detalle_facturado!A2:A100000,"<"&BQ38+1,Detalle_facturado!Q2:Q100000,"Procesamiento") -> 0 | BS38: =SUMIFS(Detalle_facturado!T2:T100000,Detalle_facturado!A2:A100000,">="&BQ38,Detalle_facturado!A2:A100000,"<"&BQ38+1,Detalle_facturado!Q2:Q100000,"Plataforma - Producción y Soporte") -> 336638.66 | BT38: =SUMIFS(Detalle_facturado!T2:T100000,Detalle_facturado!A2:A100000,">="&BQ38,Detalle_facturado!A2:A100000,"<"&BQ38+1,Detalle_facturado!Q2:Q100000,"Plataforma - Ambiente de Pruebas") -> 545937.73
AK39: Elastic Load Balancing | AL39: =SUMIF(Detalle_facturado!F2:F100000,AK39,Detalle_facturado!W2:W100000) -> 901633.71 | AM39: =RANK(AL39,$AL$13:$AL$76,0)+COUNTIF($AL$13:AL39,AL39)-1 -> 14 | AY39: =IF(AY38<INT(MAX(Detalle_facturado!A2:A100000)),AY38+1,NA()) -> 46254 | AZ39: =IF(ISNA(AY39),NA(),SUMIFS(Detalle_facturado!W2:W100000,Detalle_facturado!A2:A100000,">="&AY39,Detalle_facturado!A2:A100000,"<"&AY39+1)) -> 888944.08 | BA39: =IF(ISNA(AY39),NA(),SUMIFS(Detalle_facturado!T2:T100000,Detalle_facturado!A2:A100000,">="&AY39,Detalle_facturado!A2:A100000,"<"&AY39+1)) -> 888944.08 | BQ39: =AY39 -> 46254 | BR39: =SUMIFS(Detalle_facturado!T2:T100000,Detalle_facturado!A2:A100000,">="&BQ39,Detalle_facturado!A2:A100000,"<"&BQ39+1,Detalle_facturado!Q2:Q100000,"Procesamiento") -> 0 | BS39: =SUMIFS(Detalle_facturado!T2:T100000,Detalle_facturado!A2:A100000,">="&BQ39,Detalle_facturado!A2:A100000,"<"&BQ39+1,Detalle_facturado!Q2:Q100000,"Plataforma - Producción y Soporte") -> 342899.14 | BT39: =SUMIFS(Detalle_facturado!T2:T100000,Detalle_facturado!A2:A100000,">="&BQ39,Detalle_facturado!A2:A100000,"<"&BQ39+1,Detalle_facturado!Q2:Q100000,"Plataforma - Ambiente de Pruebas") -> 546044.94
AK40: Amazon VPC | AL40: =SUMIF(Detalle_facturado!F2:F100000,AK40,Detalle_facturado!W2:W100000) -> 463939.21 | AM40: =RANK(AL40,$AL$13:$AL$76,0)+COUNTIF($AL$13:AL40,AL40)-1 -> 15 | AY40: =IF(AY39<INT(MAX(Detalle_facturado!A2:A100000)),AY39+1,NA()) -> 46255 | AZ40: =IF(ISNA(AY40),NA(),SUMIFS(Detalle_facturado!W2:W100000,Detalle_facturado!A2:A100000,">="&AY40,Detalle_facturado!A2:A100000,"<"&AY40+1)) -> 1460310.4 | BA40: =IF(ISNA(AY40),NA(),SUMIFS(Detalle_facturado!T2:T100000,Detalle_facturado!A2:A100000,">="&AY40,Detalle_facturado!A2:A100000,"<"&AY40+1)) -> 1460310.4 | BQ40: =AY40 -> 46255 | BR40: =SUMIFS(Detalle_facturado!T2:T100000,Detalle_facturado!A2:A100000,">="&BQ40,Detalle_facturado!A2:A100000,"<"&BQ40+1,Detalle_facturado!Q2:Q100000,"Procesamiento") -> 0 | BS40: =SUMIFS(Detalle_facturado!T2:T100000,Detalle_facturado!A2:A100000,">="&BQ40,Detalle_facturado!A2:A100000,"<"&BQ40+1,Detalle_facturado!Q2:Q100000,"Plataforma - Producción y Soporte") -> 340352.81 | BT40: =SUMIFS(Detalle_facturado!T2:T100000,Detalle_facturado!A2:A100000,">="&BQ40,Detalle_facturado!A2:A100000,"<"&BQ40+1,Detalle_facturado!Q2:Q100000,"Plataforma - Ambiente de Pruebas") -> 1119957.6
AK41: Amazon Route 53 | AL41: =SUMIF(Detalle_facturado!F2:F100000,AK41,Detalle_facturado!W2:W100000) -> 14623.764 | AM41: =RANK(AL41,$AL$13:$AL$76,0)+COUNTIF($AL$13:AL41,AL41)-1 -> 34 | AY41: =IF(AY40<INT(MAX(Detalle_facturado!A2:A100000)),AY40+1,NA()) -> 46256 | AZ41: =IF(ISNA(AY41),NA(),SUMIFS(Detalle_facturado!W2:W100000,Detalle_facturado!A2:A100000,">="&AY41,Detalle_facturado!A2:A100000,"<"&AY41+1)) -> 876459.09 | BA41: =IF(ISNA(AY41),NA(),SUMIFS(Detalle_facturado!T2:T100000,Detalle_facturado!A2:A100000,">="&AY41,Detalle_facturado!A2:A100000,"<"&AY41+1)) -> 876459.09 | BQ41: =AY41 -> 46256 | BR41: =SUMIFS(Detalle_facturado!T2:T100000,Detalle_facturado!A2:A100000,">="&BQ41,Detalle_facturado!A2:A100000,"<"&BQ41+1,Detalle_facturado!Q2:Q100000,"Procesamiento") -> 0 | BS41: =SUMIFS(Detalle_facturado!T2:T100000,Detalle_facturado!A2:A100000,">="&BQ41,Detalle_facturado!A2:A100000,"<"&BQ41+1,Detalle_facturado!Q2:Q100000,"Plataforma - Producción y Soporte") -> 344300.94 | BT41: =SUMIFS(Detalle_facturado!T2:T100000,Detalle_facturado!A2:A100000,">="&BQ41,Detalle_facturado!A2:A100000,"<"&BQ41+1,Detalle_facturado!Q2:Q100000,"Plataforma - Ambiente de Pruebas") -> 532158.15
...

Sheet Por_cuenta
A1: Cuenta AWS | B1: Nombre de la cuenta | C1: Ambiente | D1: Rubro | E1: Costo AWS (USD) | F1: Tasa de cambio (COP/USD) | G1: Costo AWS (COP) | H1: Tarifa de licenciamiento | I1: Costo licenciamiento (COP) | J1: Total facturable (COP)
A2: 798406098406 | B2: ADRES - PROD - Medical Audit | C2: Prod | D2: Procesamiento | E2: 17852.599 | F2: =Resumen!$C$27 -> 3655.16 | G2: =E2*F2 -> 65254104 | H2: =Resumen!$C$28 -> 0.76 | I2: =IF(D2="Procesamiento",G2*H2,0) -> 49593119 | J2: =SUM(G2,I2) -> 1.1484722e+08

Sheet Por_servicio
A1: Servicio AWS | B1: Código de producto AWS | C1: Código de servicio AWS | D1: Rubro | E1: Costo AWS (USD) | F1: Tasa de cambio (COP/USD) | G1: Costo AWS (COP) | H1: Tarifa de licenciamiento | I1: Costo licenciamiento (COP) | J1: Total facturable (COP) | K1: Categoria principal
A2: Claude Opus 4.6 (Amazon Bedrock Edition) | B2: 3jkxki7g66gt6v02m7pqlqyyx | C2: 3jkxki7g66gt6v02m7pqlqyyx | D2: Procesamiento | E2: 17282.948 | F2: =Resumen!$C$27 -> 3655.16 | G2: =E2*F2 -> 63171941 | H2: =Resumen!$C$28 -> 0.76 | I2: =IF(D2="Procesamiento",G2*H2,0) -> 48010675 | J2: =SUM(G2,I2) -> 1.1118262e+08 | K2: GenAI

Sheet Cuenta_servicio_uso
A1: Cuenta AWS | B1: Nombre de la cuenta | C1: Servicio AWS | D1: Modelo o detalle del servicio | E1: Concepto facturado por AWS | F1: Operación AWS | G1: Unidad de facturación | H1: Rubro | I1: Cantidad reportada por AWS | J1: Costo AWS (USD) | K1: Tasa de cambio (COP/USD) | L1: Costo AWS (COP) | M1: Tarifa de licenciamiento | N1: Costo licenciamiento (COP) | O1: Total facturable (COP) | P1: Categoria principal
A2: 798406098406 | B2: ADRES - PROD - Medical Audit | C2: Claude Opus 4.6 (Amazon Bedrock Edition) | D2: Claude Opus 4.6 (Amazon Bedrock Edition) | E2: USE1-MP:USE1_InputTokenCount_Global-Units | F2: InvokeModelInference | G2: 1M tokens | H2: Procesamiento | I2: 1778.0328 | J2: 8890.164 | K2: =Resumen!$C$27 -> 3655.16 | L2: =J2*K2 -> 32494972 | M2: =Resumen!$C$28 -> 0.76 | N2: =IF(H2="Procesamiento",L2*M2,0) -> 24696179 | O2: =SUM(L2,N2) -> 57191150 | P2: GenAI

Sheet Analisis
A1: Categoría | B1: Procesamiento + Plataforma Producción y Soporte | C1: Otros rubros | D1: Total | F1: =A1 -> Categoría | G1: =B1 -> Procesamiento + Plataforma Producción y Soporte | H1: =C1 -> Otros rubros | I1: =D1 -> Total
